Workbook
Name cbr: 'Flexible Pavement Design'!$D$48

Sheet Flexible Pavement Design
B6: Traffic data
B7: Period | C7: Feb, 2016
B8: Toll Plaza | C8: Khalapur
B9: Direction | C9: Mumbai to Pune
B10: Remarks | C10: Axle load survey for 10 days on Khalapur toll plaza
B11: Source | C11: Annexture 8 - Daily Tollable Toll Collection Traffic Count and Revenue Entry Details
B12: Reference | C12: https://msrdc.in/Site/Upload/GR/Khalapur%20YCEW%20Feb%202016.pdf
B15: Date | C15: Car | D15: Bus | E15: Truck | F15: LCV | G15: MAV | H15: 3 Axle
B16: 42401 | C16: 7461 | D16: 784 | E16: 602 | F16: 1362 | G16: 435 | H16: 385
B17: =B16+3 -> 42404 | C17: 7683 | D17: 726 | E17: 639 | F17: 1493 | G17: 480 | H17: 494
B18: =B17+3 -> 42407 | C18: 10262 | D18: 838 | E18: 342 | F18: 1027 | G18: 399 | H18: 275
B19: =B18+3 -> 42410 | C19: 8160 | D19: 770 | E19: 617 | F19: 1469 | G19: 445 | H19: 511
B20: =B19+3 -> 42413 | C20: 11548 | D20: 902 | E20: 679 | F20: 1577 | G20: 473 | H20: 520
B21: =B20+3 -> 42416 | C21: 7580 | D21: 758 | E21: 649 | F21: 1406 | G21: 450 | H21: 477
B22: =B21+3 -> 42419 | C22: 10122 | D22: 834 | E22: 526 | F22: 1428 | G22: 422 | H22: 414
B23: =B22+3 -> 42422 | C23: 10011 | D23: 1036 | E23: 1042 | F23: 2023 | G23: 584 | H23: 597
B24: =B23+3 -> 42425 | C24: 7793 | D24: 759 | E24: 652 | F24: 1467 | G24: 465 | H24: 479
B25: =B24+3 -> 42428 | C25: 9911 | D25: 884 | E25: 382 | F25: 1098 | G25: 396 | H25: 309
B26: Average Traffic | C26: =AVERAGE(C16:C25) -> 9053.1 | D26: =AVERAGE(D16:D25) -> 829.1 | E26: =AVERAGE(E16:E25) -> 613 | F26: =AVERAGE(F16:F25) -> 1435 | G26: =AVERAGE(G16:G25) -> 454.9 | H26: =AVERAGE(H16:H25) -> 446.1
B27: % composition | C27: =C26/(SUM($C$26:$H$26)) -> 0.70555365 | D27: =D26/(SUM($C$26:$H$26)) -> 0.064615936 | E27: =E26/(SUM($C$26:$H$26)) -> 0.047774175 | F27: =F26/(SUM($C$26:$H$26)) -> 0.11183677 | G27: =G26/(SUM($C$26:$H$26)) -> 0.035452647 | H27: =H26/(SUM($C$26:$H$26)) -> 0.034766818
B30: Calculation for VDF
C32: Car | E32: Bus | G32: Truck | I32: LCV | K32: MAV | M32: 3 Axle | P32: Reference
B33: Average weight (in kg) | C33: 1700 | E33: 10000 | G33: 18500 | I33: 5000 | K33: 45500 | M33: 28000 | P33: https://truckindia.co.in/m&hcv-gvw-gcw-payload-unladen-weight-commercial-vehicle-category-english.html
B34: Axle type | C34: Front axle | D34: Rear axle | E34: Front axle | F34: Rear axle | G34: Front axle | H34: Rear axle | I34: Front axle | J34: Rear axle | K34: Front axle | L34: Rear axle | M34: Front axle | N34: Rear axle
B35: Axle load distribution | C35: =$C$33/2 -> 850 | D35: =$C$33/2 -> 850 | E35: =$E$33/3 -> 3333.3333 | F35: =$E$33*2/3 -> 6666.6667 | G35: =$G$33/5 -> 3700 | H35: =$G$33*4/5 -> 14800 | I35: =$I$33/2 -> 2500 | J35: =$I$33/2 -> 2500 | K35: =$K$33*2/5 -> 18200 | L35: =$K$33*3/5 -> 27300 | M35: =$M$33/4 -> 7000 | N35: =$M$33*3/4 -> 21000 | P35: # All front axle are single axle with single wheel, Rear axle for car is single axle with single wheel, for bus is single axle with dual wheel, for truck is tandem axle, for LCV is single axle with single wheel, for MAV is tridem axle, for 3 Axle is tandem axle
B36: VDF | C36: =(C35*10/1000/65)^4 -> 0.00029243024 | D36: =(D35*10/1000/65)^4 -> 0.00029243024 | E36: =(E35*10/1000/65)^4 -> 0.069161046 | F36: =(F35*10/1000/80)^4 -> 0.48225309 | G36: =(G35*10/1000/65)^4 -> 0.10499134 | H36: =(H35*10/1000/148)^4 -> 1 | I36: =(I35*10/1000/65)^4 -> 0.021882987 | J36: =(J35*10/1000/65)^4 -> 0.021882987 | K36: =(K35*10/1000/65)^4 -> 61.4656 | L36: =(L35*10/1000/224)^4 -> 2.2062693 | M36: =(M35*10/1000/65)^4 -> 1.3450509 | N36: =(N35*10/1000/148)^4 -> 4.0535013
B37: Total VDF | C37: =C36+D36 -> 0.00058486047 | E37: =E36+F36 -> 0.55141413 | G37: =G36+H36 -> 1.1049913 | I37: =I36+J36 -> 0.043765975 | K37: =K36+L36 -> 63.671869 | M37: =M36+N36 -> 5.3985523
B38: Count | C38: =C26 -> 9053.1 | E38: =D26 -> 829.1 | G38: =E26 -> 613 | I38: =F26 -> 1435 | K38: =G26 -> 454.9 | M38: =H26 -> 446.1
B39: Weighted Average VDF | C39: =(C37*C38+E37*E38+G37*G38+I37*I38+K37*K38+M37*M38)/SUM(C38:M38) -> 2.5387543
B42: Design parameters
B44: VDF | D44: =C39 -> 2.5387543 | I44: CVPD in one direction | L44: =SUM(D26:H26) -> 3778.1
B45: LDF | D45: 0.6 | E45: # For three lane in each direction | I45: Construction Period (in years) | L45: 2
B46: n (Design life in years) | D46: 20 | I46: Mix design parameters of bituminous layer
B47: r (rate of traffic growth annually) | D47: 0.075 | E47: # As per IRC-37-2001 | I47: Air voids | L47: 0.03
B48: Effective CBR | D48: 9 | I48: Effective bitumen content | L48: 0.115
B50: Design Process
B51: Step 1 -> Calculate the no of CVPD in the year of completion of construction
B52: A (in CVPD) | C52: =L44*(1+D47)^L45 -> 4366.0668
B53: Calculate the no of CVPD in the design life of 20 years
B54: N (in MSA) | C54: =365*C52*((1+D47)^D46-1)*D44*D45/D47/1000000 -> 105.12113
...

Sheet Rigid Pavement Design

Sheet Cost Estimation
B6: Flexible Pavement | O6: Rigid Pavement
B8: Dimensions | O8: Dimensions
B9: Length (in km) | C9: 94.5 | E9: # The width of a single lane in multilane road is 3.5m. So for 6 lane is 3.5*6 = 21m. And the minimum width of paved shoulder is 1.5m and unpaved shoulder is 2m. So total width of shoulder on both sides including is 2*(1.5+2) = 7m. The minimum width of divider is 2.5m. The clearnce between lane and divider is 0.5 m thus for both sides total clearnce is 0.5*2 = 1m. | O9: Length (in km) | P9: 94.5 | R9: # The width of a single lane in multilane road is 3.5m. So for 6 lane is 3.5*6 = 21m. And the minimum width of paved shoulder is 1.5m and unpaved shoulder is 2m. So total width of shoulder on both sides including is 2*(1.5+2) = 7m. The minimum width of divider is 2.5m. The clearnce between lane and divider is 0.5 m thus for both sides total clearnce is 0.5*2 = 1m.
B10: Width (in m) | C10: =3.5*6+2*(1.5+2)+2.5+0.5*2 -> 31.5 | O10: Width (in m) | P10: =3.5*6+2*(1.5+2)+2.5+0.5*2 -> 31.5
B13: Thickness (in mm) | O13: Thickness of each layer (in mm)
B14: ='Flexible Pavement Design'!B57 -> Layer | C14: ='Flexible Pavement Design'!C57 -> Thickness (in mm) | O14: PQC slab | P14: 300
B15: ='Flexible Pavement Design'!B58 -> BC (Surface Layer) | C15: ='Flexible Pavement Design'!C58 -> 40 | O15: DLC | P15: 150
B16: ='Flexible Pavement Design'!B59 -> Binder coarse | C16: ='Flexible Pavement Design'!C59 -> 120 | O16: GSB as Drainage layer | P16: 250
B17: ='Flexible Pavement Design'!B60 -> Base (WMM) | C17: ='Flexible Pavement Design'!C60 -> 250 | O17: GSB as Seperation layer | P17: 150
B18: ='Flexible Pavement Design'!B61 -> GSB | C18: ='Flexible Pavement Design'!C61 -> 200 | O18: Subgrade | P18: 500
B21: Excavation cost | O21: Excavation cost
B33: Material Cost | O33: Material Cost
B49: Construction Cost | O49: Construction Cost
B65: Maintenance Cost | O65: Maintenance Cost
B80: Results | O80: Results
B81: Initial cost | O81: Initial cost
B82: Annual operation cost | O82: Annual operation cost
B83: Maintenance cost | O83: Maintenance cost
B84: Design life | O84: Design life
S85: Harsh

Sheet Cash Flow
B6: Flexible Pavement | L6: Flexible Pavement
B8: Initial construction cost | C8: =100000 -> 100000
B9: Routine maintenance cost | C9: 20000
B10: Periodic maintenance cost | C10: 30000
B11: Rehabiliation cost
B12: Salvage value
B13: Fuel cost
B14: Time saving benefits

Sheet Financial Analysis

Sheet Economic Analysis

Sheet Risk Analysis
